<?xml version="1.0" ?>
<robot name="Manipulador" xmlns:xacro="http://www.ros.org/wiki/xacro">

<xacro:include filename="$(find Manipulador_description)/urdf/materials.xacro" />
<xacro:include filename="$(find Manipulador_description)/urdf/Manipulador.trans" />
<xacro:include filename="$(find Manipulador_description)/urdf/Manipulador.gazebo" />
<link name="base_link">
  <inertial>
    <origin xyz="0.0 4.129580929120314e-17 0.028013158131108173" rpy="0 0 0"/>
    <mass value="0.8644380061148665"/>
    <inertia ixx="0.001136" iyy="0.001136" izz="0.001604" ixy="0.0" iyz="-0.0" ixz="-0.0"/>
  </inertial>
  <visual>
    <origin xyz="0 0 0" rpy="0 0 0"/>
    <geometry>
      <mesh filename="file://$(find Manipulador_description)/meshes/base_link.stl" scale="0.001 0.001 0.001"/>
    </geometry>
    <material name="silver"/>
  </visual>
  <collision>
    <origin xyz="0 0 0" rpy="0 0 0"/>
    <geometry>
      <mesh filename="file://$(find Manipulador_description)/meshes/base_link.stl" scale="0.001 0.001 0.001"/>
    </geometry>
  </collision>
</link>

<link name="base_cima_1">
  <inertial>
    <origin xyz="1.1970149693281284e-14 1.9829071827633267e-17 0.018193196281490173" rpy="0 0 0"/>
    <mass value="0.6751009456259592"/>
    <inertia ixx="0.000924" iyy="0.000555" izz="0.000645" ixy="-0.0" iyz="-0.0" ixz="0.0"/>
  </inertial>
  <visual>
    <origin xyz="-0.0 -0.0 -0.0669" rpy="0 0 0"/>
    <geometry>
      <mesh filename="file://$(find Manipulador_description)/meshes/base_cima_1.stl" scale="0.001 0.001 0.001"/>
    </geometry>
    <material name="silver"/>
  </visual>
  <collision>
    <origin xyz="-0.0 -0.0 -0.0669" rpy="0 0 0"/>
    <geometry>
      <mesh filename="file://$(find Manipulador_description)/meshes/base_cima_1.stl" scale="0.001 0.001 0.001"/>
    </geometry>
  </collision>
</link>

<link name="braco1_1">
  <inertial>
    <origin xyz="-2.740279011686726e-15 0.0275 0.049401867400451355" rpy="0 0 0"/>
    <mass value="1.7863299950890772"/>
    <inertia ixx="0.003721" iyy="0.003209" izz="0.000967" ixy="-0.0" iyz="0.0" ixz="0.0"/>
  </inertial>
  <visual>
    <origin xyz="0.0 0.0275 -0.1172" rpy="0 0 0"/>
    <geometry>
      <mesh filename="file://$(find Manipulador_description)/meshes/braco1_1.stl" scale="0.001 0.001 0.001"/>
    </geometry>
    <material name="silver"/>
  </visual>
  <collision>
    <origin xyz="0.0 0.0275 -0.1172" rpy="0 0 0"/>
    <geometry>
      <mesh filename="file://$(find Manipulador_description)/meshes/braco1_1.stl" scale="0.001 0.001 0.001"/>
    </geometry>
  </collision>
</link>

<link name="braco2_1">
  <inertial>
    <origin xyz="1.8642595259125363e-15 0.0275 0.03974999999999998" rpy="0 0 0"/>
    <mass value="1.833463405716618"/>
    <inertia ixx="0.002376" iyy="0.002348" izz="0.000597" ixy="0.0" iyz="0.0" ixz="-0.0"/>
  </inertial>
  <visual>
    <origin xyz="-0.0 0.0275 -0.2422" rpy="0 0 0"/>
    <geometry>
      <mesh filename="file://$(find Manipulador_description)/meshes/braco2_1.stl" scale="0.001 0.001 0.001"/>
    </geometry>
    <material name="silver"/>
  </visual>
  <collision>
    <origin xyz="-0.0 0.0275 -0.2422" rpy="0 0 0"/>
    <geometry>
      <mesh filename="file://$(find Manipulador_description)/meshes/braco2_1.stl" scale="0.001 0.001 0.001"/>
    </geometry>
  </collision>
</link>

<link name="braco3_1">
  <inertial>
    <origin xyz="-0.008884231331327241 0.027499999999999997 0.042248373954598184" rpy="0 0 0"/>
    <mass value="2.0477712972739655"/>
    <inertia ixx="0.002084" iyy="0.001584" izz="0.001847" ixy="0.0" iyz="-0.0" ixz="9.9e-05"/>
  </inertial>
  <visual>
    <origin xyz="-0.0 0.0275 -0.3217" rpy="0 0 0"/>
    <geometry>
      <mesh filename="file://$(find Manipulador_description)/meshes/braco3_1.stl" scale="0.001 0.001 0.001"/>
    </geometry>
    <material name="silver"/>
  </visual>
  <collision>
    <origin xyz="-0.0 0.0275 -0.3217" rpy="0 0 0"/>
    <geometry>
      <mesh filename="file://$(find Manipulador_description)/meshes/braco3_1.stl" scale="0.001 0.001 0.001"/>
    </geometry>
  </collision>
</link>

<link name="garra_base_1">
  <inertial>
    <origin xyz="-1.0054196140392503e-14 -4.834082544152743e-14 0.018196855600843498" rpy="0 0 0"/>
    <mass value="0.16038383685906207"/>
    <inertia ixx="8.6e-05" iyy="4.6e-05" izz="5.9e-05" ixy="0.0" iyz="0.0" ixz="-0.0"/>
  </inertial>
  <visual>
    <origin xyz="-0.0 -0.0 -0.39885" rpy="0 0 0"/>
    <geometry>
      <mesh filename="file://$(find Manipulador_description)/meshes/garra_base_1.stl" scale="0.001 0.001 0.001"/>
    </geometry>
    <material name="silver"/>
  </visual>
  <collision>
    <origin xyz="-0.0 -0.0 -0.39885" rpy="0 0 0"/>
    <geometry>
      <mesh filename="file://$(find Manipulador_description)/meshes/garra_base_1.stl" scale="0.001 0.001 0.001"/>
    </geometry>
  </collision>
</link>

<link name="garra_esquerda_1">
  <inertial>
    <origin xyz="0.0 -0.007993386734000607 0.05263724971926159" rpy="0 0 0"/>
    <mass value="0.03761222131658412"/>
    <inertia ixx="2.4e-05" iyy="2.2e-05" izz="2e-06" ixy="0.0" iyz="5e-06" ixz="0.0"/>
  </inertial>
  <visual>
    <origin xyz="-0.0 -0.02 -0.44885" rpy="0 0 0"/>
    <geometry>
      <mesh filename="file://$(find Manipulador_description)/meshes/garra_esquerda_1.stl" scale="0.001 0.001 0.001"/>
    </geometry>
    <material name="silver"/>
  </visual>
  <collision>
    <origin xyz="-0.0 -0.02 -0.44885" rpy="0 0 0"/>
    <geometry>
      <mesh filename="file://$(find Manipulador_description)/meshes/garra_esquerda_1.stl" scale="0.001 0.001 0.001"/>
    </geometry>
  </collision>
</link>

<link name="garra_direita_1">
  <inertial>
    <origin xyz="2.3171326867272047e-19 0.007993386734000405 0.05263724971926148" rpy="0 0 0"/>
    <mass value="0.037612221316584114"/>
    <inertia ixx="2.4e-05" iyy="2.2e-05" izz="2e-06" ixy="0.0" iyz="-5e-06" ixz="0.0"/>
  </inertial>
  <visual>
    <origin xyz="-0.0 0.02 -0.44885" rpy="0 0 0"/>
    <geometry>
      <mesh filename="file://$(find Manipulador_description)/meshes/garra_direita_1.stl" scale="0.001 0.001 0.001"/>
    </geometry>
    <material name="silver"/>
  </visual>
  <collision>
    <origin xyz="-0.0 0.02 -0.44885" rpy="0 0 0"/>
    <geometry>
      <mesh filename="file://$(find Manipulador_description)/meshes/garra_direita_1.stl" scale="0.001 0.001 0.001"/>
    </geometry>
  </collision>
</link>

<joint name="base_cima_to_base_link" type="continuous">
  <origin xyz="0.0 0.0 0.0669" rpy="0 0 0"/>
  <parent link="base_link"/>
  <child link="base_cima_1"/>
  <axis xyz="0.0 0.0 -1.0"/>
</joint>

<joint name="braco1_to_base_cima" type="continuous">
  <origin xyz="-0.0 -0.0275 0.0503" rpy="0 0 0"/>
  <parent link="base_cima_1"/>
  <child link="braco1_1"/>
  <axis xyz="0.0 -1.0 0.0"/>
</joint>

<joint name="braco2_to_braco1" type="continuous">
  <origin xyz="0.0 0.0 0.125" rpy="0 0 0"/>
  <parent link="braco1_1"/>
  <child link="braco2_1"/>
  <axis xyz="0.0 -1.0 0.0"/>
</joint>

<joint name="braco3_to_braco2" type="continuous">
  <origin xyz="0.0 0.0 0.0795" rpy="0 0 0"/>
  <parent link="braco2_1"/>
  <child link="braco3_1"/>
  <axis xyz="0.0 -1.0 0.0"/>
</joint>

<joint name="garra_base_to braco3" type="continuous">
  <origin xyz="0.0 0.0275 0.07715" rpy="0 0 0"/>
  <parent link="braco3_1"/>
  <child link="garra_base_1"/>
  <axis xyz="0.0 0.0 1.0"/>
</joint>

<joint name="garra_esquerda_to_garra_base" type="prismatic">
  <origin xyz="0.0 0.02 0.05" rpy="0 0 0"/>
  <parent link="garra_base_1"/>
  <child link="garra_esquerda_1"/>
  <axis xyz="0.0 -1.0 0.0"/>
  <limit upper="0.0" lower="-0.025" effort="100" velocity="100.0"/>
</joint>

<joint name="garra_direita_to_garra_base" type="prismatic">
  <origin xyz="0.0 -0.02 0.05" rpy="0 0 0"/>
  <parent link="garra_base_1"/>
  <child link="garra_direita_1"/>
  <axis xyz="0.0 1.0 0.0"/>
  <limit upper="0.025" lower="0.0" effort="100" velocity="100.0"/>
  <mimic joint="garra_esquerda_to_garra_base"/>
</joint>

</robot>
