<?xml version="1.0" ?>
<robot name="robot" xmlns:xacro="http://www.ros.org/wiki/xacro">

    <xacro:include filename="$(find simulation_pkg)/urdf/robot.gazebo"/>


    <!-- root link, on the ground just below the model origin -->
    <link name="base_footprint">
        <visual>
            <origin xyz="0 0 0" rpy="0 0 0" />
            <geometry>
                <box size="0.001 0.001 0.001" />
            </geometry>
        </visual>
    </link>

    <joint name="base_link_joint" type="fixed">
        <origin xyz="0.0 0 1.25" rpy="0 0 0" />
        <parent link="base_footprint" />
        <child link="base_link" />
    </joint>

    <link name="base_link">
        <visual>
            <origin xyz="0.068650503425891296061 -0.083840399074440033478 0.040443740433454548888"
                rpy="0 -0 0" />
            <geometry>
                <mesh filename="file://$(find simulation_pkg)/meshes/stl/lidar.stl" />
            </geometry>
            <material name="lidar_material">
                <color
                    rgba="0.61568627450980395466 0.81176470588235294379 0.92941176470588238168 1.0" />
            </material>
        </visual>
        <collision>
            <origin xyz="0.068650503425891296061 -0.083840399074440033478 0.040443740433454548888"
                rpy="0 -0 0" />
            <geometry>
                <mesh filename="file://$(find simulation_pkg)/meshes/stl/lidar.stl" />
            </geometry>
        </collision>
        <visual>
            <origin xyz="0.11731235416125289361 0.15179281777659742181 -0.009556259566545493786"
                rpy="0 -0 -0.52359877559829881566" />
            <geometry>
                <mesh filename="file://$(find simulation_pkg)/meshes/stl/perfil_colunas.stl" />
            </geometry>
            <material name="perfil_colunas_material">
                <color
                    rgba="0.90196078431372550543 0.90196078431372550543 0.90196078431372550543 1.0" />
            </material>
        </visual>
        <collision>
            <origin xyz="0.11731235416125289361 0.15179281777659742181 -0.009556259566545493786"
                rpy="0 -0 -0.52359877559829881566" />
            <geometry>
                <mesh filename="file://$(find simulation_pkg)/meshes/stl/perfil_colunas.stl" />
            </geometry>
        </collision>
        <visual>
            <origin xyz="0.017124847813541788089 -0.021737033501267377655 0.034443740433454550498"
                rpy="0 -0 0" />
            <geometry>
                <mesh filename="file://$(find simulation_pkg)/meshes/stl/mdf_motores.stl" />
            </geometry>
            <material name="mdf_motores_material">
                <color
                    rgba="0.90196078431372550543 0.83529411764705885357 0.6745098039215686736 1.0" />
            </material>
        </visual>
        <collision>
            <origin xyz="0.017124847813541788089 -0.021737033501267377655 0.034443740433454550498"
                rpy="0 -0 0" />
            <geometry>
                <mesh filename="file://$(find simulation_pkg)/meshes/stl/mdf_motores.stl" />
            </geometry>
        </collision>
        <visual>
            <origin xyz="-0.18325016488188017316 -0.0217370335012673499 -0.009556259566545493786"
                rpy="0 -0 1.57079632679489678" />
            <geometry>
                <mesh filename="file://$(find simulation_pkg)/meshes/stl/perfil_colunas.stl" />
            </geometry>
            <material name="perfil_colunas_material">
                <color
                    rgba="0.90196078431372550543 0.90196078431372550543 0.90196078431372550543 1.0" />
            </material>
        </visual>
        <collision>
            <origin xyz="-0.18325016488188017316 -0.0217370335012673499 -0.009556259566545493786"
                rpy="0 -0 1.57079632679489678" />
            <geometry>
                <mesh filename="file://$(find simulation_pkg)/meshes/stl/perfil_colunas.stl" />
            </geometry>
        </collision>
        <visual>
            <origin xyz="0.070294802381689489024 -0.064708319082856041726 0.031443740433454547833"
                rpy="0 -0 0" />
            <geometry>
                <mesh filename="file://$(find simulation_pkg)/meshes/stl/imu.stl" />
            </geometry>
            <material name="imu_material">
                <color
                    rgba="0.64705882352941179736 0.64705882352941179736 0.64705882352941179736 1.0" />
            </material>
        </visual>
        <collision>
            <origin xyz="0.070294802381689489024 -0.064708319082856041726 0.031443740433454547833"
                rpy="0 -0 0" />
            <geometry>
                <mesh filename="file://$(find simulation_pkg)/meshes/stl/imu.stl" />
            </geometry>
        </collision>
        <visual>
            <origin xyz="0.11731235416125274096 -0.19526688477913226039 -0.009556259566545493786"
                rpy="0 -0 -2.6179938779914944114" />
            <geometry>
                <mesh filename="file://$(find simulation_pkg)/meshes/stl/perfil_colunas.stl" />
            </geometry>
            <material name="perfil_colunas_material">
                <color
                    rgba="0.90196078431372550543 0.90196078431372550543 0.90196078431372550543 1.0" />
            </material>
        </visual>
        <collision>
            <origin xyz="0.11731235416125274096 -0.19526688477913226039 -0.009556259566545493786"
                rpy="0 -0 -2.6179938779914944114" />
            <geometry>
                <mesh filename="file://$(find simulation_pkg)/meshes/stl/perfil_colunas.stl" />
            </geometry>
        </collision>
        <visual>
            <origin xyz="0.094662354161252709739 -0.15603593398769710632 -0.059198882331824187464"
                rpy="0 -0 0.52359877559829881566" />
            <geometry>
                <mesh filename="file://$(find simulation_pkg)/meshes/stl/motor.stl" />
            </geometry>
            <material name="motor_material">
                <color rgba="0.7568627450980391913 0.6745098039215686736 0.5803921568627451455 1.0" />
            </material>
        </visual>
        <collision>
            <origin xyz="0.094662354161252709739 -0.15603593398769710632 -0.059198882331824187464"
                rpy="0 -0 0.52359877559829881566" />
            <geometry>
                <mesh filename="file://$(find simulation_pkg)/meshes/stl/motor.stl" />
            </geometry>
        </collision>
        <visual>
            <origin xyz="0.1208123541612529106 0.15785499560308846601 -0.025556259566545502793"
                rpy="0 -0 2.6179938779914944114" />
            <geometry>
                <mesh filename="file://$(find simulation_pkg)/meshes/stl/perfil_motores.stl" />
            </geometry>
            <material name="perfil_motores_material">
                <color
                    rgba="0.90196078431372550543 0.90196078431372550543 0.90196078431372550543 1.0" />
            </material>
        </visual>
        <collision>
            <origin xyz="0.1208123541612529106 0.15785499560308846601 -0.025556259566545502793"
                rpy="0 -0 2.6179938779914944114" />
            <geometry>
                <mesh filename="file://$(find simulation_pkg)/meshes/stl/perfil_motores.stl" />
            </geometry>
        </collision>
        <visual>
            <origin xyz="0.12081235416125274407 -0.20132906260562333234 -0.025556259566545502793"
                rpy="0 -0 0.52359877559829881566" />
            <geometry>
                <mesh filename="file://$(find simulation_pkg)/meshes/stl/perfil_motores.stl" />
            </geometry>
            <material name="perfil_motores_material">
                <color
                    rgba="0.90196078431372550543 0.90196078431372550543 0.90196078431372550543 1.0" />
            </material>
        </visual>
        <collision>
            <origin xyz="0.12081235416125274407 -0.20132906260562333234 -0.025556259566545502793"
                rpy="0 -0 0.52359877559829881566" />
            <geometry>
                <mesh filename="file://$(find simulation_pkg)/meshes/stl/perfil_motores.stl" />
            </geometry>
        </collision>
        <visual>
            <origin xyz="0.017124847813541788089 -0.021737033501267377655 -0.015556259566545493911"
                rpy="0 -0 0" />
            <geometry>
                <mesh filename="file://$(find simulation_pkg)/meshes/stl/mdf_motores.stl" />
            </geometry>
            <material name="mdf_motores_material">
                <color
                    rgba="0.90196078431372550543 0.83529411764705885357 0.6745098039215686736 1.0" />
            </material>
        </visual>
        <collision>
            <origin xyz="0.017124847813541788089 -0.021737033501267377655 -0.015556259566545493911"
                rpy="0 -0 0" />
            <geometry>
                <mesh filename="file://$(find simulation_pkg)/meshes/stl/mdf_motores.stl" />
            </geometry>
        </collision>
        <visual>
            <origin xyz="-0.19025016488188017938 -0.0217370335012673499 -0.025556259566545502793"
                rpy="0 -0 -1.570796326794896558" />
            <geometry>
                <mesh filename="file://$(find simulation_pkg)/meshes/stl/perfil_motores.stl" />
            </geometry>
            <material name="perfil_motores_material">
                <color
                    rgba="0.90196078431372550543 0.90196078431372550543 0.90196078431372550543 1.0" />
            </material>
        </visual>
        <collision>
            <origin xyz="-0.19025016488188017938 -0.0217370335012673499 -0.025556259566545502793"
                rpy="0 -0 -1.570796326794896558" />
            <geometry>
                <mesh filename="file://$(find simulation_pkg)/meshes/stl/perfil_motores.stl" />
            </geometry>
        </collision>
        <visual>
            <origin xyz="0.094662354161252904028 0.11256186698516235101 -0.059198882331824187464"
                rpy="-5.5511151231257827021e-17 -0 2.6179938779914944114" />
            <geometry>
                <mesh filename="file://$(find simulation_pkg)/meshes/stl/motor.stl" />
            </geometry>
            <material name="motor_material">
                <color rgba="0.7568627450980391913 0.6745098039215686736 0.5803921568627451455 1.0" />
            </material>
        </visual>
        <collision>
            <origin xyz="0.094662354161252904028 0.11256186698516235101 -0.059198882331824187464"
                rpy="-5.5511151231257827021e-17 -0 2.6179938779914944114" />
            <geometry>
                <mesh filename="file://$(find simulation_pkg)/meshes/stl/motor.stl" />
            </geometry>
        </collision>
        <visual>
            <origin xyz="-0.13795016488188016623 -0.021737033501267322144 -0.059198882331824187464"
                rpy="0 -0 -1.570796326794896558" />
            <geometry>
                <mesh filename="file://$(find simulation_pkg)/meshes/stl/motor.stl" />
            </geometry>
            <material name="motor_material">
                <color rgba="0.7568627450980391913 0.6745098039215686736 0.5803921568627451455 1.0" />
            </material>
        </visual>
        <collision>
            <origin xyz="-0.13795016488188016623 -0.021737033501267322144 -0.059198882331824187464"
                rpy="0 -0 -1.570796326794896558" />
            <geometry>
                <mesh filename="file://$(find simulation_pkg)/meshes/stl/motor.stl" />
            </geometry>
        </collision>
        <inertial>
            <origin xyz="0.017124847813541812375 -0.021737033501267381125 0.10031955161546367294"
                rpy="0 0 0" />
            <mass value="6.6882194661599978502" />
            <inertia ixx="0.44905529509685665479" ixy="-1.9346232515288219744e-17"
                ixz="-1.7347234759768070944e-18" iyy="0.44905529509685659928"
                iyz="1.5524419857276816614e-17" izz="0.21703524056640266515" />
        </inertial>
    </link>

    <link name="roda">
        <visual>
            <origin
                xyz="-1.3877787807814456755e-17 6.9388939039072283776e-18 -0.019000000000000016875"
                rpy="1.570796326794896558 7.4370840716688178931e-17 -1.232595164407830946e-32" />
            <geometry>
                <mesh filename="file://$(find simulation_pkg)/meshes/stl/roda.stl" />
            </geometry>
            <material name="roda_material">
                <color
                    rgba="0.30196078431372547213 0.30196078431372547213 0.30196078431372547213 1.0" />
            </material>
        </visual>
        <collision>
            <origin
                xyz="-1.3877787807814456755e-17 6.9388939039072283776e-18 -0.019000000000000016875"
                rpy="1.570796326794896558 7.4370840716688178931e-17 -1.232595164407830946e-32" />
            <geometry>
                <mesh filename="file://$(find simulation_pkg)/meshes/stl/roda.stl" />
            </geometry>
        </collision>
        <inertial>
            <origin xyz="-1.3870615907766392849e-17 2.0994022695976859463e-18 -0.018457929616132112"
                rpy="0 0 0" />
            <mass value="0.28213445289600003196" />
            <inertia ixx="0.00028668585825496428711" ixy="-5.6238678373927387656e-36"
                ixz="-2.1054995767594193363e-20" iyy="0.00028668585825496428711"
                iyz="-1.9351439587697641709e-35" izz="0.00049830179002104330651" />
        </inertial>
    </link>

    <joint name="wheel1_speed" type="continuous">
        <origin xyz="0.14081735231077155412 0.17690466880337613054 -0.059198882331824187464"
            rpy="1.57079632679489678 -2.7755575615628882696e-17 -0.52359877559829870464" />
        <parent link="base_link" />
        <child link="roda" />
        <axis xyz="0 0 1" />
        <limit effort="1" velocity="20" />
        <joint_properties friction="0.0" />
    </joint>

    <link name="roda_2">
        <visual>
            <origin
                xyz="-2.168404344971008868e-18 6.9388939039072283776e-18 -0.019000000000000016875"
                rpy="1.570796326794896558 -6.2948235302926546307e-17 0" />
            <geometry>
                <mesh filename="file://$(find simulation_pkg)/meshes/stl/roda.stl" />
            </geometry>
            <material name="roda_material">
                <color
                    rgba="0.30196078431372547213 0.30196078431372547213 0.30196078431372547213 1.0" />
            </material>
        </visual>
        <collision>
            <origin
                xyz="-2.168404344971008868e-18 6.9388939039072283776e-18 -0.019000000000000016875"
                rpy="1.570796326794896558 -6.2948235302926546307e-17 0" />
            <geometry>
                <mesh filename="file://$(find simulation_pkg)/meshes/stl/roda.stl" />
            </geometry>
        </collision>
        <inertial>
            <origin xyz="-2.157490465055410453e-18 2.0994022695976859463e-18 -0.018457929616132112"
                rpy="0 0 0" />
            <mass value="0.28213445289600003196" />
            <inertia ixx="0.00028668585825496428711" ixy="0" ixz="2.175228116890445513e-20"
                iyy="0.00028668585825496428711" iyz="0" izz="0.00049830179002104330651" />
        </inertial>
    </link>

    <joint name="wheel2_speed" type="continuous">
        <origin xyz="0.12730735601173409632 -0.22817873580591085947 -0.059198882331824180525"
            rpy="-1.570796326794896558 -0 0.52359877559829881566" />
        <parent link="base_link" />
        <child link="roda_2" />
        <axis xyz="0 0 1" />
        <limit effort="1" velocity="20" />
        <joint_properties friction="0.0" />
    </joint>

    <link name="roda_3">
        <visual>
            <origin
                xyz="1.7347234759768070944e-18 6.9388939039072283776e-18 -0.01899999999999998912"
                rpy="1.570796326794896558 -0 0" />
            <geometry>
                <mesh filename="file://$(find simulation_pkg)/meshes/stl/roda.stl" />
            </geometry>
            <material name="roda_material">
                <color
                    rgba="0.30196078431372547213 0.30196078431372547213 0.30196078431372547213 1.0" />
            </material>
        </visual>
        <collision>
            <origin
                xyz="1.7347234759768070944e-18 6.9388939039072283776e-18 -0.01899999999999998912"
                rpy="1.570796326794896558 -0 0" />
            <geometry>
                <mesh filename="file://$(find simulation_pkg)/meshes/stl/roda.stl" />
            </geometry>
        </collision>
        <inertial>
            <origin
                xyz="1.7416059328748181195e-18 2.0994022695976859463e-18 -0.018457929616132084244"
                rpy="0 0 0" />
            <mass value="0.28213445289600003196" />
            <inertia ixx="0.00028668585825496428711" ixy="0" ixz="0" iyy="0.00028668585825496428711"
                iyz="0" izz="0.00049830179002104330651" />
        </inertial>
    </link>

    <joint name="wheel3_speed" type="continuous">
        <origin xyz="-0.21675016488188014741 -0.013937033501267319033 -0.059198882331824180525"
            rpy="-1.570796326794896558 -0 -1.570796326794896558" />
        <parent link="base_link" />
        <child link="roda_3" />
        <axis xyz="0 0 1" />
        <limit effort="1" velocity="20" />
        <joint_properties friction="0.0" />
    </joint>


</robot>